Workbook

Sheet  Sales_Data
B1: Date | C1: MONTH | D1: Center | E1: Course | F1: Category | G1: Region | H1: Quantity | I1: Fee | J1: Revenue
B2: 45658 | C2: =TEXT(B2, "mmm-yyyy") -> Jan-2025 | D2: Banglore | E2: Data Analytics | F2: Professional | G2: South | H2: 5 | I2: 30000 | J2: =$H2*$I2 -> 150000
B3: 45689 | C3: =TEXT(B3, "mmm-yyyy") -> Feb-2025 | D3: Mysore | E3: Data Science | F3: Professional | G3: South | H3: 10 | I3: 45000 | J3: =$H3*$I3 -> 450000
B4: 45717 | C4: =TEXT(B4, "mmm-yyyy") -> Mar-2025 | D4: Hubli | E4: Data Analytics | F4: Professional | G4: South | H4: 15 | I4: 30000 | J4: =$H4*$I4 -> 450000
B5: 45748 | C5: =TEXT(B5, "mmm-yyyy") -> Apr-2025 | D5: Banglore | E5: Data Science | F5: Professional | G5: South | H5: 16 | I5: 45000 | J5: =$H5*$I5 -> 720000
B6: 45778 | C6: =TEXT(B6, "mmm-yyyy") -> May-2025 | D6: Mysore | E6: Data Analytics | F6: Professional | G6: South | H6: 18 | I6: 30000 | J6: =$H6*$I6 -> 540000
B7: 45809 | C7: =TEXT(B7, "mmm-yyyy") -> Jun-2025 | D7: Hubli | E7: Data Science | F7: Professional | G7: South | H7: 20 | I7: 45000 | J7: =$H7*$I7 -> 900000
B8: 45839 | C8: =TEXT(B8, "mmm-yyyy") -> Jul-2025 | D8: Banglore | E8: Data Analytics | F8: Professional | G8: South | H8: 25 | I8: 30000 | J8: =$H8*$I8 -> 750000
B9: 45870 | C9: =TEXT(B9, "mmm-yyyy") -> Aug-2025 | D9: Mysore | E9: Data Science | F9: Professional | G9: South | H9: 26 | I9: 45000 | J9: =$H9*$I9 -> 1170000
B10: 45901 | C10: =TEXT(B10, "mmm-yyyy") -> Sep-2025 | D10: Hubli | E10: Data Analytics | F10: Professional | G10: South | H10: 29 | I10: 30000 | J10: =$H10*$I10 -> 870000
B11: 45931 | C11: =TEXT(B11, "mmm-yyyy") -> Oct-2025 | D11: Banglore | E11: Data Science | F11: Professional | G11: South | H11: 30 | I11: 45000 | J11: =$H11*$I11 -> 1350000
B12: 45962 | C12: =TEXT(B12, "mmm-yyyy") -> Nov-2025 | D12: Mysore | E12: Data Analytics | F12: Professional | G12: South | H12: 35 | I12: 30000 | J12: =$H12*$I12 -> 1050000
B13: 45992 | C13: =TEXT(B13, "mmm-yyyy") -> Dec-2025 | D13: Hubli | E13: Data Science | F13: Professional | G13: South | H13: 40 | I13: 45000 | J13: =$H13*$I13 -> 1800000
C14: =TEXT(B14, "mmm-yyyy")
C15: =TEXT(B15, "mmm-yyyy")
C16: =TEXT(B16, "mmm-yyyy")
C17: =TEXT(B17, "mmm-yyyy")
C18: =TEXT(B18, "mmm-yyyy")
C19: =TEXT(B19, "mmm-yyyy")
C20: =TEXT(B20, "mmm-yyyy")
C21: =TEXT(B21, "mmm-yyyy")
C22: =TEXT(B22, "mmm-yyyy")
C23: =TEXT(B23, "mmm-yyyy")
C24: =TEXT(B24, "mmm-yyyy")
C25: =TEXT(B25, "mmm-yyyy")
... C731: =TEXT(B731, "mmm-yyyy")

Sheet  Sales_Dashboard
C7: KPI 1: Total Revenue (₹) | F7: KPI 2: Total Enrollment (₹) | I7: KPI 3: Average Monthly Revenue (₹)
C8: =SUM(' Sales_Data'!J:J) -> 10200000 | F8: =SUM(' Sales_Data'!H:H) -> 269 | I8: =AVERAGE(' Sales_Data'!J2:J13) -> 850000
C9: Revenue by Course
C10: Row Labels | D10: Sum of Revenue | F10: Row Labels | G10: Sum of Quantity | I10: Row Labels | J10: Sum of Revenue
C11: Banglore | D11: 2970000 | F11: Data Analytics | G11: 127 | I11: Apr-2025 | J11: 720000
C12: Hubli | D12: 4020000 | F12: Data Science | G12: 142 | I12: Aug-2025 | J12: 1170000
C13: Mysore | D13: 3210000 | F13: (blank) | I13: Dec-2025 | J13: 1800000
C14: (blank) | F14: Grand Total | G14: 269 | I14: Feb-2025 | J14: 450000
C15: Grand Total | D15: 10200000 | I15: Jan-2025 | J15: 150000
I16: Jul-2025 | J16: 750000
I17: Jun-2025 | J17: 900000
I18: Mar-2025 | J18: 450000
I19: May-2025 | J19: 540000
I20: Nov-2025 | J20: 1050000
I21: Oct-2025 | J21: 1350000
I22: Sep-2025 | J22: 870000
I23: Grand Total | J23: 10200000
C35: Key Insights | F35: Recommendations
C37: Data Science has higher enrollments compared to Data Analytics | F37: Strengthen promotion during low-revenue months
C39: Revenue shows growth with peak performance towards year end | F39: Focus on high-demand courses like Data Science
C41: Monthly revenue fluctuates, indicating seasonal trends | F41: Plan capacity expansion for peak periods

Sheet  Student_Retention_Data
A1: Student ID | B1: Center | C1: Course | D1: Join Date | E1: Expected End Date | F1: Actual End Date | G1: Status | H1: Fee | I1: Lifetime (Months) | J1: Churn Flag
A2: STU001 | B2: Banglore | C2: Data Analytics | D2: 45658 | E2: =EDATE(D2,6) -> 45839 | F2: =E2 -> 45839 | G2: Completed | H2: =IF(C2="Data Analytics",30000,45000) -> 30000 | I2: =IFERROR(IF(OR(F2="",F2<D2),"",DATEDIF(D2,F2,"M")),"") -> 6 | J2: =IF(G2="Dropped",1,0) -> 0
A3: STU002 | B3: Mysore | C3: Data Science | D3: 45689 | E3: =EDATE(D3,6) -> 45870 | F3: 45778 | G3: Dropped | H3: =IF(C3="Data Analytics",30000,45000) -> 45000 | I3: =IFERROR(IF(OR(F3="",F3<D3),"",DATEDIF(D3,F3,"M")),"") -> 3 | J3: =IF(G3="Dropped",1,0) -> 1
A4: STU003 | B4: Hubli | C4: Data Analytics | D4: 45717 | E4: =EDATE(D4,6) -> 45901 | G4: Active | H4: =IF(C4="Data Analytics",30000,45000) -> 30000 | I4: =IFERROR(IF(OR(F4="",F4<D4),"",DATEDIF(D4,F4,"M")),"") | J4: =IF(G4="Dropped",1,0) -> 0
A5: STU004 | B5: Banglore | C5: Data Science | D5: 45748 | E5: =EDATE(D5,6) -> 45931 | F5: =E5 -> 45931 | G5: Completed | H5: =IF(C5="Data Analytics",30000,45000) -> 45000 | I5: =IFERROR(IF(OR(F5="",F5<D5),"",DATEDIF(D5,F5,"M")),"") -> 6 | J5: =IF(G5="Dropped",1,0) -> 0
A6: STU005 | B6: Mysore | C6: Data Analytics | D6: 45778 | E6: =EDATE(D6,6) -> 45962 | F6: 01-08-2025 | G6: Dropped | H6: =IF(C6="Data Analytics",30000,45000) -> 30000 | I6: =IFERROR(IF(OR(F6="",F6<D6),"",DATEDIF(D6,F6,"M")),"") | J6: =IF(G6="Dropped",1,0) -> 1
A7: STU006 | B7: Hubli | C7: Data Science | D7: 45809 | E7: =EDATE(D7,6) -> 45992 | F7: =E7 -> 45992 | G7: Completed | H7: =IF(C7="Data Analytics",30000,45000) -> 45000 | I7: =IFERROR(IF(OR(F7="",F7<D7),"",DATEDIF(D7,F7,"M")),"") -> 6 | J7: =IF(G7="Dropped",1,0) -> 0
A8: STU007 | B8: Banglore | C8: Data Analytics | D8: 45839 | E8: =EDATE(D8,6) -> 46023 | F8: 45779 | G8: Dropped | H8: =IF(C8="Data Analytics",30000,45000) -> 30000 | I8: =IFERROR(IF(OR(F8="",F8<D8),"",DATEDIF(D8,F8,"M")),"") | J8: =IF(G8="Dropped",1,0) -> 1
A9: STU008 | B9: Mysore | C9: Data Science | D9: 45870 | E9: =EDATE(D9,6) -> 46054 | G9: Active | H9: =IF(C9="Data Analytics",30000,45000) -> 45000 | I9: =IFERROR(IF(OR(F9="",F9<D9),"",DATEDIF(D9,F9,"M")),"") | J9: =IF(G9="Dropped",1,0) -> 0
A10: STU009 | B10: Hubli | C10: Data Analytics | D10: 45901 | E10: =EDATE(D10,6) -> 46082 | F10: =E10 -> 46082 | G10: Completed | H10: =IF(C10="Data Analytics",30000,45000) -> 30000 | I10: =IFERROR(IF(OR(F10="",F10<D10),"",DATEDIF(D10,F10,"M")),"") -> 6 | J10: =IF(G10="Dropped",1,0) -> 0
A11: STU010 | B11: Banglore | C11: Data Science | D11: 45931 | E11: =EDATE(D11,6) -> 46113 | F11: 01-08-2026 | G11: Dropped | H11: =IF(C11="Data Analytics",30000,45000) -> 45000 | I11: =IFERROR(IF(OR(F11="",F11<D11),"",DATEDIF(D11,F11,"M")),"") | J11: =IF(G11="Dropped",1,0) -> 1
A12: STU011 | B12: Mysore | C12: Data Analytics | D12: 45962 | E12: =EDATE(D12,6) -> 46143 | F12: =E12 -> 46143 | G12: Completed | H12: =IF(C12="Data Analytics",30000,45000) -> 30000 | I12: =IFERROR(IF(OR(F12="",F12<D12),"",DATEDIF(D12,F12,"M")),"") -> 6 | J12: =IF(G12="Dropped",1,0) -> 0
A13: STU012 | B13: Hubli | C13: Data Science | D13: 45992 | E13: =EDATE(D13,6) -> 46174 | F13: =D13+90 -> 46082 | G13: Dropped | H13: =IF(C13="Data Analytics",30000,45000) -> 45000 | I13: =IFERROR(IF(OR(F13="",F13<D13),"",DATEDIF(D13,F13,"M")),"") -> 3 | J13: =IF(G13="Dropped",1,0) -> 1
A14: STU013 | B14: Banglore | C14: Data Analytics | D14: 46023 | E14: =EDATE(D14,6) -> 46204 | G14: Active | H14: =IF(C14="Data Analytics",30000,45000) -> 30000 | I14: =IFERROR(IF(OR(F14="",F14<D14),"",DATEDIF(D14,F14,"M")),"") | J14: =IF(G14="Dropped",1,0) -> 0
A15: STU014 | B15: Mysore | C15: Data Science | D15: 46054 | E15: =EDATE(D15,6) -> 46235 | F15: =E15 -> 46235 | G15: Completed | H15: =IF(C15="Data Analytics",30000,45000) -> 45000 | I15: =IFERROR(IF(OR(F15="",F15<D15),"",DATEDIF(D15,F15,"M")),"") -> 6 | J15: =IF(G15="Dropped",1,0) -> 0
A16: STU015 | B16: Hubli | C16: Data Analytics | D16: 46082 | E16: =EDATE(D16,6) -> 46266 | F16: 01-08-2027 | G16: Dropped | H16: =IF(C16="Data Analytics",30000,45000) -> 30000 | I16: =IFERROR(IF(OR(F16="",F16<D16),"",DATEDIF(D16,F16,"M")),"") | J16: =IF(G16="Dropped",1,0) -> 1
A17: STU016 | B17: Banglore | C17: Data Science | D17: 46113 | E17: =EDATE(D17,6) -> 46296 | F17: =E17 -> 46296 | G17: Completed | H17: =IF(C17="Data Analytics",30000,45000) -> 45000 | I17: =IFERROR(IF(OR(F17="",F17<D17),"",DATEDIF(D17,F17,"M")),"") -> 6 | J17: =IF(G17="Dropped",1,0) -> 0
A18: STU017 | B18: Mysore | C18: Data Analytics | D18: 46143 | E18: =EDATE(D18,6) -> 46327 | F18: 45781 | G18: Dropped | H18: =IF(C18="Data Analytics",30000,45000) -> 30000 | I18: =IFERROR(IF(OR(F18="",F18<D18),"",DATEDIF(D18,F18,"M")),"") | J18: =IF(G18="Dropped",1,0) -> 1
A19: STU018 | B19: Hubli | C19: Data Science | D19: 46174 | E19: =EDATE(D19,6) -> 46357 | G19: Active | H19: =IF(C19="Data Analytics",30000,45000) -> 45000 | I19: =IFERROR(IF(OR(F19="",F19<D19),"",DATEDIF(D19,F19,"M")),"") | J19: =IF(G19="Dropped",1,0) -> 0
A20: STU019 | B20: Banglore | C20: Data Analytics | D20: 46204 | E20: =EDATE(D20,6) -> 46388 | F20: =E20 -> 46388 | G20: Completed | H20: =IF(C20="Data Analytics",30000,45000) -> 30000 | I20: =IFERROR(IF(OR(F20="",F20<D20),"",DATEDIF(D20,F20,"M")),"") -> 6 | J20: =IF(G20="Dropped",1,0) -> 0
A21: STU020 | B21: Mysore | C21: Data Science | D21: 46235 | E21: =EDATE(D21,6) -> 46419 | F21: 01-08-2028 | G21: Dropped | H21: =IF(C21="Data Analytics",30000,45000) -> 45000 | I21: =IFERROR(IF(OR(F21="",F21<D21),"",DATEDIF(D21,F21,"M")),"") | J21: =IF(G21="Dropped",1,0) -> 1
A22: STU021 | B22: Hubli | C22: Data Analytics | D22: 46266 | E22: =EDATE(D22,6) -> 46447 | F22: =E22 -> 46447 | G22: Completed | H22: =IF(C22="Data Analytics",30000,45000) -> 30000 | I22: =IFERROR(IF(OR(F22="",F22<D22),"",DATEDIF(D22,F22,"M")),"") -> 6 | J22: =IF(G22="Dropped",1,0) -> 0
A23: STU022 | B23: Banglore | C23: Data Science | D23: 46296 | E23: =EDATE(D23,6) -> 46478 | F23: 45782 | G23: Dropped | H23: =IF(C23="Data Analytics",30000,45000) -> 45000 | I23: =IFERROR(IF(OR(F23="",F23<D23),"",DATEDIF(D23,F23,"M")),"") | J23: =IF(G23="Dropped",1,0) -> 1
A24: STU023 | B24: Mysore | C24: Data Analytics | D24: 46327 | E24: =EDATE(D24,6) -> 46508 | G24: Active | H24: =IF(C24="Data Analytics",30000,45000) -> 30000 | I24: =IFERROR(IF(OR(F24="",F24<D24),"",DATEDIF(D24,F24,"M")),"") | J24: =IF(G24="Dropped",1,0) -> 0
A25: STU024 | B25: Hubli | C25: Data Science | D25: 46357 | E25: =EDATE(D25,6) -> 46539 | F25: =E25 -> 46539 | G25: Completed | H25: =IF(C25="Data Analytics",30000,45000) -> 45000 | I25: =IFERROR(IF(OR(F25="",F25<D25),"",DATEDIF(D25,F25,"M")),"") -> 6 | J25: =IF(G25="Dropped",1,0) -> 0
A26: STU025 | B26: Banglore | C26: Data Analytics | D26: 46388 | E26: =EDATE(D26,6) -> 46569 | F26: 01-08-2029 | G26: Dropped | H26: =IF(C26="Data Analytics",30000,45000) -> 30000 | I26: =IFERROR(IF(OR(F26="",F26<D26),"",DATEDIF(D26,F26,"M")),"") | J26: =IF(G26="Dropped",1,0) -> 1
A27: STU026 | B27: Mysore | C27: Data Science | D27: 46419 | E27: =EDATE(D27,6) -> 46600 | F27: =E27 -> 46600 | G27: Completed | H27: =IF(C27="Data Analytics",30000,45000) -> 45000 | I27: =IFERROR(IF(OR(F27="",F27<D27),"",DATEDIF(D27,F27,"M")),"") -> 6 | J27: =IF(G27="Dropped",1,0) -> 0
A28: STU027 | B28: Hubli | C28: Data Analytics | D28: 46447 | E28: =EDATE(D28,6) -> 46631 | F28: 45783 | G28: Dropped | H28: =IF(C28="Data Analytics",30000,45000) -> 30000 | I28: =IFERROR(IF(OR(F28="",F28<D28),"",DATEDIF(D28,F28,"M")),"") | J28: =IF(G28="Dropped",1,0) -> 1
A29: STU028 | B29: Banglore | C29: Data Science | D29: 46478 | E29: =EDATE(D29,6) -> 46661 | G29: Active | H29: =IF(C29="Data Analytics",30000,45000) -> 45000 | I29: =IFERROR(IF(OR(F29="",F29<D29),"",DATEDIF(D29,F29,"M")),"") | J29: =IF(G29="Dropped",1,0) -> 0
A30: STU029 | B30: Mysore | C30: Data Analytics | D30: 46508 | E30: =EDATE(D30,6) -> 46692 | F30: =E30 -> 46692 | G30: Completed | H30: =IF(C30="Data Analytics",30000,45000) -> 30000 | I30: =IFERROR(IF(OR(F30="",F30<D30),"",DATEDIF(D30,F30,"M")),"") -> 6 | J30: =IF(G30="Dropped",1,0) -> 0
A31: STU030 | B31: Hubli | C31: Data Science | D31: 46539 | E31: =EDATE(D31,6) -> 46722 | F31: 01-08-2030 | G31: Dropped | H31: =IF(C31="Data Analytics",30000,45000) -> 45000 | I31: =IFERROR(IF(OR(F31="",F31<D31),"",DATEDIF(D31,F31,"M")),"") | J31: =IF(G31="Dropped",1,0) -> 1
A32: STU031 | B32: Banglore | C32: Data Analytics | D32: 46569 | E32: =EDATE(D32,6) -> 46753 | F32: =E32 -> 46753 | G32: Completed | H32: =IF(C32="Data Analytics",30000,45000) -> 30000 | I32: =IFERROR(IF(OR(F32="",F32<D32),"",DATEDIF(D32,F32,"M")),"") -> 6 | J32: =IF(G32="Dropped",1,0) -> 0
A33: STU032 | B33: Mysore | C33: Data Science | D33: 46600 | E33: =EDATE(D33,6) -> 46784 | F33: 45784 | G33: Dropped | H33: =IF(C33="Data Analytics",30000,45000) -> 45000 | I33: =IFERROR(IF(OR(F33="",F33<D33),"",DATEDIF(D33,F33,"M")),"") | J33: =IF(G33="Dropped",1,0) -> 1
A34: STU033 | B34: Hubli | C34: Data Analytics | D34: 46631 | E34: =EDATE(D34,6) -> 46813 | G34: Active | H34: =IF(C34="Data Analytics",30000,45000) -> 30000 | I34: =IFERROR(IF(OR(F34="",F34<D34),"",DATEDIF(D34,F34,"M")),"") | J34: =IF(G34="Dropped",1,0) -> 0
A35: STU034 | B35: Banglore | C35: Data Science | D35: 46661 | E35: =EDATE(D35,6) -> 46844 | F35: =E35 -> 46844 | G35: Completed | H35: =IF(C35="Data Analytics",30000,45000) -> 45000 | I35: =IFERROR(IF(OR(F35="",F35<D35),"",DATEDIF(D35,F35,"M")),"") -> 6 | J35: =IF(G35="Dropped",1,0) -> 0
A36: STU035 | B36: Mysore | C36: Data Analytics | D36: 46692 | E36: =EDATE(D36,6) -> 46874 | F36: 01-08-2031 | G36: Dropped | H36: =IF(C36="Data Analytics",30000,45000) -> 30000 | I36: =IFERROR(IF(OR(F36="",F36<D36),"",DATEDIF(D36,F36,"M")),"") | J36: =IF(G36="Dropped",1,0) -> 1
A37: STU036 | B37: Hubli | C37: Data Science | D37: 46722 | E37: =EDATE(D37,6) -> 46905 | F37: =E37 -> 46905 | G37: Completed | H37: =IF(C37="Data Analytics",30000,45000) -> 45000 | I37: =IFERROR(IF(OR(F37="",F37<D37),"",DATEDIF(D37,F37,"M")),"") -> 6 | J37: =IF(G37="Dropped",1,0) -> 0
A38: STU037 | B38: Banglore | C38: Data Analytics | D38: 46753 | E38: =EDATE(D38,6) -> 46935 | F38: 45785 | G38: Dropped | H38: =IF(C38="Data Analytics",30000,45000) -> 30000 | I38: =IFERROR(IF(OR(F38="",F38<D38),"",DATEDIF(D38,F38,"M")),"") | J38: =IF(G38="Dropped",1,0) -> 1
A39: STU038 | B39: Mysore | C39: Data Science | D39: 46784 | E39: =EDATE(D39,6) -> 46966 | G39: Active | H39: =IF(C39="Data Analytics",30000,45000) -> 45000 | I39: =IFERROR(IF(OR(F39="",F39<D39),"",DATEDIF(D39,F39,"M")),"") | J39: =IF(G39="Dropped",1,0) -> 0
A40: STU039 | B40: Hubli | C40: Data Analytics | D40: 46813 | E40: =EDATE(D40,6) -> 46997 | F40: =E40 -> 46997 | G40: Completed | H40: =IF(C40="Data Analytics",30000,45000) -> 30000 | I40: =IFERROR(IF(OR(F40="",F40<D40),"",DATEDIF(D40,F40,"M")),"") -> 6 | J40: =IF(G40="Dropped",1,0) -> 0
...

Sheet  Retention_Dashboard
B2: KPI 1: Total Students | E2: KPI 2: Churn Rate % | H2: KPI 3: Retention Rate % | L2: KPI 4: Avg Student Lifetime (Months)
B3: =COUNTA([1]Student_Retention_Data!A2:A51) -> 50 | E3: =SUM(' Student_Retention_Data'!J2:J52)/COUNTA(' Student_Retention_Data'!A2:A51) -> 0.4 | H3: =1-G6 -> 1 | L3: =AVERAGE(' Student_Retention_Data'!I2:I52) -> 5.6956522
B5: Row Labels | C5: Sum of Churn Flag | E5: Row Labels | F5: Sum of Churn Flag | H5: Row Labels | I5: Count of Student ID | J5: Sum of Churn Flag
B6: Data Analytics | C6: 10 | E6: Banglore | F6: 6 | H6: Active | I6: 10 | J6: 0 | M6: Row Labels | N6: Average of Lifetime (Months)
B7: Data Science | C7: 10 | E7: Hubli | F7: 6 | H7: Completed | I7: 20 | J7: 0 | M7: Data Analytics | N7: 6
B8: Grand Total | C8: 20 | E8: Mysore | F8: 8 | H8: Dropped | I8: 20 | J8: 20 | M8: Data Science | N8: 5.5
E9: Grand Total | F9: 20 | H9: Grand Total | I9: 50 | J9: 20 | M9: Grand Total | N9: 5.7272727
B26: Key Insights | G26: Recommendations
B27: Certain courses show higher student churn | G27: Improve onboarding in first 2–3 months
B28: Some centers experience more dropouts than others | G28: Provide extra support for high-churn centers
B29: Average student lifetime differs by course | G29: Monitor early engagement indicators

Sheet  Marketing_Funnel_Data
A1: Center | B1: Channel | C1: Visitors | D1: Enquiries | E1: Counselling | F1: Enrollments | G1: Marketing Cost | H1: Visit → Enquiry % | I1: Enquiry → Enrollment % | J1: Cost per Enrollment | K1: Column1 | L1: Column2 | M1: Column3
A2: Bangalore | B2: Instagram | C2: 1200 | D2: 180 | E2: 90 | F2: 45 | G2: 30000 | H2: =D2/C2 -> 0.15 | I2: =F2/D2 -> 0.25 | J2: =G2/F2 -> 666.66667
A3: Bangalore | B3: Website | C3: 900 | D3: 150 | E3: 80 | F3: 40 | G3: 25000 | H3: =D3/C3 -> 0.16666667 | I3: =F3/D3 -> 0.26666667 | J3: =G3/F3 -> 625
A4: Mysore | B4: Instagram | C4: 700 | D4: 90 | E4: 40 | F4: 18 | G4: 15000 | H4: =D4/C4 -> 0.12857143 | I4: =F4/D4 -> 0.2 | J4: =G4/F4 -> 833.33333
A5: Mysore | B5: Referral | C5: 400 | D5: 120 | E5: 100 | F5: 60 | G5: 10000 | H5: =D5/C5 -> 0.3 | I5: =F5/D5 -> 0.5 | J5: =G5/F5 -> 166.66667

Sheet Sheet1
A1: Center | B1: Channel | C1: Visitors | D1: Enquiries | E1: Counselling | F1: Enrollments | G1: Marketing Cost | H1: Visit → Enquiry % | I1: Enquiry → Enrollment % | J1: Cost per Enrollment
A2: Bangalore | B2: Instagram | C2: 1200 | D2: 180 | E2: 90 | F2: 45 | G2: 30000 | H2: 0.15 | I2: 0.25 | J2: 666.66667
A3: Bangalore | B3: Website | C3: 900 | D3: 150 | E3: 80 | F3: 40 | G3: 25000 | H3: 0.16666667 | I3: 0.26666667 | J3: 625
A4: Mysore | B4: Instagram | C4: 700 | D4: 90 | E4: 40 | F4: 18 | G4: 15000 | H4: 0.12857143 | I4: 0.2 | J4: 833.33333
A5: Mysore | B5: Referral | C5: 400 | D5: 120 | E5: 100 | F5: 60 | G5: 10000 | H5: 0.3 | I5: 0.5 | J5: 166.66667

Sheet  Funnel_Dashboard
A1: Total Enrollments | E1: Avg Cost per Enrollment
A2: 163 | E2: 40.75
A6: Row Labels | B6: Sum of Enrollments | D6: Row Labels | E6: Average of Enrollments
A7: Instagram | B7: 63 | D7: Instagram | E7: 31.5
A8: Referral | B8: 60 | D8: Referral | E8: 60
A9: Website | B9: 40 | D9: Website | E9: 40
A10: Grand Total | B10: 163 | D10: Grand Total | E10: 40.75
AE24: Sum of Enrollments
AE25: 163 | AF25: 3200
